<?xml version='1.0'?>

<robot name="li_bot" xmlns:xacro="http://www.ros.org/wiki/xacro">
  <xacro:include filename="$(find li_bot)/urdf/li_bot.gazebo" />

  <link name="robot_footprint"></link>

  <joint name="robot_footprint_joint" type="fixed">
    <origin xyz="0 0 0" rpy="0 0 0" />
    <parent link="robot_footprint"/>
    <child link="chassis" />
  </joint>

  <link name='chassis'>
    <pose>0 0 0.1 0 0 0</pose>

    <inertial>
      <mass value="15.0"/>
      <origin xyz="0.0 0 0" rpy=" 0 0 0"/>
      <inertia
          ixx="0.1" ixy="0" ixz="0"
          iyy="0.1" iyz="0"
          izz="0.1"
      />
    </inertial>

    <collision name='collision'>
      <origin xyz="0 0 0" rpy=" 0 0 0"/> 
      <geometry>
        <box size=".4 .2 .1"/>
      </geometry>
    </collision>

    <visual name='chassis_visual'>
      <origin xyz="0 0 0" rpy=" 0 0 0"/>
      <geometry>
        <box size=".4 .2 .1"/>
      </geometry>
      <material name="blue">
        <color rgba="0 0 0.8 1"/>
      </material>
    </visual>


    <collision name='back_caster_collision'>
      <origin xyz="-0.15 0 -0.05" rpy=" 0 0 0"/>
      <geometry>
        <sphere radius="0.05"/>
      </geometry>
      <surface>
        <friction>
          <ode>
            <mu>0</mu>
            <mu2>0</mu2>
            <slip1>1.0</slip1>
            <slip2>1.0</slip2>
          </ode>
        </friction>
      </surface>
    </collision>

    <visual name='back_caster_visual'>
      <origin xyz="-0.15 0 -0.05" rpy=" 0 0 0"/>
      <geometry>
        <sphere radius="0.05"/>
      </geometry>
    </visual>

    <collision name='front_caster_collision'>
      <origin xyz="0.15 0 -0.05" rpy=" 0 0 0"/>
      <geometry>
        <sphere radius="0.05"/>
      </geometry>
      <surface>
        <friction>
          <ode>
            <mu>0</mu>
            <mu2>0</mu2>
            <slip1>1.0</slip1>
            <slip2>1.0</slip2>
          </ode>
        </friction>
      </surface>
    </collision>

    <visual name='front_caster_visual'>
      <origin xyz="0.15 0 -0.05" rpy=" 0 0 0"/>
      <geometry>
        <sphere radius="0.05"/>
      </geometry>
    </visual>

  </link>




  <joint type="fixed" name="topcube_joint">
    <origin xyz="0.0 0 0.0" rpy="0 0 0"/>
    <child link="topcube"/>
    <parent link="chassis"/>
  </joint>

  <link name='topcube'>
    <inertial>
      <mass value="0.6"/>
      <origin xyz="0.1 0.0 0.1" rpy=" 0 0 0"/>
      <inertia ixx="0.1" ixy="0" ixz="0" iyy="0.1" iyz="0" izz="0.1"/>
    </inertial>
    <collision name='topcube_collision'>
      <origin xyz="0.1 0.0 0.1" rpy=" 0 0 0"/> 
      <geometry>
          <box size="0.18 0.12 0.1"/>
      </geometry>
    </collision>
    <visual name='topcube_visual'>
      <origin xyz="0.1 0.0 0.1" rpy=" 0 0 0"/>
      <geometry>
          <box size="0.18 0.12 0.1"/>
      </geometry>
      <material name="teal">
        <color rgba="0 0.8 0.8 1"/>
      </material>
    </visual>
  </link>



  <joint type="fixed" name="hokuyo_joint">
    <origin xyz="0.15 0 0.175" rpy="0 0 0"/>
    <child link="hokuyo"/>
    <parent link="topcube"/>
  </joint>

  <link name='hokuyo'>
    <inertial>
      <mass value="0.1"/>
      <origin xyz="0.0 0 0.0" rpy="0 0 0"/>
      <inertia ixx="1e-6" ixy="0" ixz="0" iyy="1e-6" iyz="0" izz="1e-6"/>
    </inertial>
    <collision name='hokuyo_collision'>
      <origin xyz="0.0 0 0.0" rpy="0 0 0"/>
      <geometry>
        <box size="0.1 0.1 0.1"/>
      </geometry>
    </collision>
    <visual name='hokuyo_visual'>
      <origin xyz="0.0 0 0.0" rpy="0 0 0"/>
      <geometry>
        <mesh filename="package://li_bot/meshes/hokuyo.dae"/>
      </geometry>
    </visual>
  </link>


  <joint type="fixed" name="leftpole_joint">
    <origin xyz="-0.16 -0.06 0.1" rpy="0 0 0"/>
    <child link="leftpole"/>
    <parent link="chassis"/>
  </joint>

  <link name='leftpole'>
    <inertial>
      <mass value="0.1"/>
      <origin xyz="0.0 0.0 0.0" rpy=" 0 0 0"/>
      <inertia ixx="1e-6" ixy="0" ixz="0" iyy="1e-6" iyz="0" izz="1e-6"/>
    </inertial>
    <collision name='leftpole_collision'>
      <origin xyz="0.0 0.0 0.0" rpy=" 0 0 0"/> 
      <geometry>
          <cylinder radius="0.02" length="0.3"/>
      </geometry>
    </collision>
    <visual name='leftpole_visual'>
      <origin xyz="0.0 0.0 0.0" rpy=" 0 0 0"/>
      <geometry>
          <cylinder radius="0.02" length="0.3"/>
      </geometry>
      <material name="yellow">
        <color rgba="0.8 0.8 0.0 1"/>
      </material>
    </visual>
  </link>

  <joint type="fixed" name="rightpole_joint">
    <origin xyz="-0.16 0.06 0.1" rpy="0 0 0"/>
    <child link="rightpole"/>
    <parent link="chassis"/>
  </joint>

  <link name='rightpole'>
    <inertial>
      <mass value="0.1"/>
      <origin xyz="0.0 0.0 0.0" rpy=" 0 0 0"/>
      <inertia ixx="1e-6" ixy="0" ixz="0" iyy="1e-6" iyz="0" izz="1e-6"/>
    </inertial>
    <collision name='rightpole_collision'>
      <origin xyz="0.0 0.0 0.0" rpy=" 0 0 0"/> 
      <geometry>
          <cylinder radius="0.02" length="0.3"/>
      </geometry>
    </collision>
    <visual name='rightpole_visual'>
      <origin xyz="0.0 0.0 0.0" rpy=" 0 0 0"/>
      <geometry>
          <cylinder radius="0.02" length="0.3"/>
      </geometry>
      <material name="yellow">
        <color rgba="0.8 0.8 0.0 1"/>
      </material>
    </visual>
  </link>









  <link name="left_wheel">
    <collision name='left_wheel_collision'>
      <origin xyz="0.0 0.0 0.0" rpy="0.0 1.5707 1.5707"/>
      <geometry>
        <cylinder radius="0.1" length="0.05"/>
      </geometry>
    </collision>
    <inertial>
      <mass value="5.0"/>
      <origin xyz="0.0 0 0" rpy="0.0 1.5707 1.5707"/>
      <inertia ixx="0.1" ixy="0" ixz="0" iyy="0.1" iyz="0" izz="0.1" />
    </inertial>
    <visual name='left_wheel_visual'>
     <origin xyz="0.0 0.0 0.0" rpy="0.0 1.5707 1.5707"/>
      <geometry>
        <cylinder radius="0.1" length="0.05"/>
      </geometry>
      <material name="green">
        <color rgba="0 0.8 0 1"/>
      </material>
    </visual>
  </link>

  <joint type="continuous" name="left_wheel_hinge">
    <origin xyz="0 0.15 0" rpy="0 0 0"/>
    <child link="left_wheel"/>
    <parent link="chassis"/>
    <axis xyz="0 1 0" rpy="0 0 0"/>
    <limit effort="10000" velocity="1000"/>
    <joint_properties damping="1.0" friction="1.0"/>
  </joint>

  <link name="right_wheel">
    <collision name='right_wheel_collision'>
      <origin xyz="0.0 0.0 0.0" rpy="0.0 1.5707 1.5707"/>
      <geometry>
        <cylinder radius="0.1" length="0.05"/>
      </geometry>
    </collision>
    <inertial>
      <mass value="5.0"/>
      <origin xyz="0.0 0.0 0.0" rpy="0.0 1.5707 1.5707"/>
      <inertia ixx="0.1" ixy="0" ixz="0" iyy="0.1" iyz="0" izz="0.1" />
    </inertial>
    <visual name='right_wheel_visual'>
      <origin xyz="0.0 0.0 0.0" rpy="0.0 1.5707 1.5707"/>
      <geometry>
        <cylinder radius="0.1" length="0.05"/>
      </geometry>
      <material name="green">
        <color rgba="0 0.8 0 1"/>
      </material>
    </visual>
  </link>

  <joint type="continuous" name="right_wheel_hinge">
    <origin xyz="0 -0.15 0" rpy="0 0 0"/>
    <child link="right_wheel"/>
    <parent link="chassis"/>
    <axis xyz="0 1 0" rpy="0 0 0"/>
    <limit effort="10000" velocity="1000"/>
    <joint_properties damping="1.0" friction="1.0"/>
  </joint>

  <link name="camera">
    <collision name='camera_collision'>
      <origin xyz="0.0 0.0 0.0" rpy=" 0.0 0.0 0.0"/>
      <geometry>
        <box size="0.05 0.05 0.05"/>
      </geometry>
    </collision>
    <inertial>
      <mass value="0.1"/>
      <origin xyz="0.0 0.0 0.0" rpy=" 0.0 0.0 0.0"/>
      <inertia ixx="1e-6" ixy="0" ixz="0" iyy="1e-6" iyz="0" izz="1e-6"/>
    </inertial>
    <visual name='camera_visual'>
      <origin xyz="0.0 0.0 0.0" rpy=" 0.0 0.0 0.0"/>
      <geometry>
        <box size="0.05 0.05 0.05"/>
      </geometry>
      <material name="red">
        <color rgba="0.8 0 0 1"/>
      </material>
    </visual>
  </link>

  <joint type="fixed" name="camera_joint">
    <origin xyz="0.2 0.0 0.0" rpy="0 0 0"/>
    <child link="camera"/>
    <parent link="chassis"/>
  </joint>











</robot>
